Workbook

Sheet Sažetak
A1: LLM-as-Judge evaluacija: Vanilla vs. RAG vs. GraphRAG (EuroLLM)
A2: Diplomski rad – usporedba arhitektura za pitanja i odgovore nad hrvatskim vojno-obrambenim propisima
A3: Ljestvica 1–5. Ocjene provjerene izravno protiv izvornih dokumenata (Ustav 2018, Zakon o obrani 2025, Zakon o službi 2025, Pravilnik o TVO, Pravilnik o službi u OSRH). n = 43 pitanja.
A5: Tablica 1. Prosječne ocjene po dimenzijama (svih 43 pitanja)
A6: Dimenzija | B6: Vanilla | C6: RAG | D6: GraphRAG
A7: Pravna točnost | B7: =AVERAGEIFS(Podaci!$C:$C,Podaci!$B:$B,"vanilla") -> 2.1627907 | C7: =AVERAGEIFS(Podaci!$C:$C,Podaci!$B:$B,"rag") -> 4.1162791 | D7: =AVERAGEIFS(Podaci!$C:$C,Podaci!$B:$B,"graph") -> 3.6511628
A8: Citiranje propisa | B8: =AVERAGEIFS(Podaci!$D:$D,Podaci!$B:$B,"vanilla") -> 1.372093 | C8: =AVERAGEIFS(Podaci!$D:$D,Podaci!$B:$B,"rag") -> 3.7674419 | D8: =AVERAGEIFS(Podaci!$D:$D,Podaci!$B:$B,"graph") -> 3.0697674
A9: Praktična primjenjivost | B9: =AVERAGEIFS(Podaci!$E:$E,Podaci!$B:$B,"vanilla") -> 2.9069767 | C9: =AVERAGEIFS(Podaci!$E:$E,Podaci!$B:$B,"rag") -> 4.2093023 | D9: =AVERAGEIFS(Podaci!$E:$E,Podaci!$B:$B,"graph") -> 3.7674419
A10: Potpunost odgovora | B10: =AVERAGEIFS(Podaci!$F:$F,Podaci!$B:$B,"vanilla") -> 2.3023256 | C10: =AVERAGEIFS(Podaci!$F:$F,Podaci!$B:$B,"rag") -> 3.8604651 | D10: =AVERAGEIFS(Podaci!$F:$F,Podaci!$B:$B,"graph") -> 3.3488372
A11: Jasnoća | B11: =AVERAGEIFS(Podaci!$G:$G,Podaci!$B:$B,"vanilla") -> 3.6744186 | C11: =AVERAGEIFS(Podaci!$G:$G,Podaci!$B:$B,"rag") -> 4.4418605 | D11: =AVERAGEIFS(Podaci!$G:$G,Podaci!$B:$B,"graph") -> 4.2325581
A12: UKUPNO | B12: =AVERAGE(B7:B11) -> 2.4837209 | C12: =AVERAGE(C7:C11) -> 4.0790698 | D12: =AVERAGE(D7:D11) -> 3.6139535
A15: Tablica 2. Ukupni skor (prosjek svih 5 dimenzija) po kategoriji pitanja
A16: Kategorija (broj pitanja) | B16: Vanilla | C16: RAG | D16: GraphRAG
A17: Jednostavna (23) | B17: =AVERAGEIFS(Podaci!$I:$I,Podaci!$B:$B,"vanilla",Podaci!$H:$H,"jednostavna_pitanja") -> 2.573913 | C17: =AVERAGEIFS(Podaci!$I:$I,Podaci!$B:$B,"rag",Podaci!$H:$H,"jednostavna_pitanja") -> 4.5304348 | D17: =AVERAGEIFS(Podaci!$I:$I,Podaci!$B:$B,"graph",Podaci!$H:$H,"jednostavna_pitanja") -> 3.9130435
A18: Kompleksna – 1 dokument (8) | B18: =AVERAGEIFS(Podaci!$I:$I,Podaci!$B:$B,"vanilla",Podaci!$H:$H,"kompleksna_pitanja_jeden_dokument") -> 2.35 | C18: =AVERAGEIFS(Podaci!$I:$I,Podaci!$B:$B,"rag",Podaci!$H:$H,"kompleksna_pitanja_jeden_dokument") -> 3.675 | D18: =AVERAGEIFS(Podaci!$I:$I,Podaci!$B:$B,"graph",Podaci!$H:$H,"kompleksna_pitanja_jeden_dokument") -> 3.275
A19: Kompleksna – više dok. (12) | B19: =AVERAGEIFS(Podaci!$I:$I,Podaci!$B:$B,"vanilla",Podaci!$H:$H,"kompleksna_pitanja_vise_dokumenata") -> 2.4 | C19: =AVERAGEIFS(Podaci!$I:$I,Podaci!$B:$B,"rag",Podaci!$H:$H,"kompleksna_pitanja_vise_dokumenata") -> 3.4833333 | D19: =AVERAGEIFS(Podaci!$I:$I,Podaci!$B:$B,"graph",Podaci!$H:$H,"kompleksna_pitanja_vise_dokumenata") -> 3.2666667
A22: Tablica 3. Statistička značajnost (na ukupnom skoru po pitanju)
A23: Usporedba | B23: p-vrijednost | C23: Zaključak
A24: Friedman test (sva 3 modela) | B24: p < 0.001 | C24: značajna razlika
A25: Wilcoxon: RAG vs GraphRAG | B25: p = 0.0001 | C25: RAG značajno bolji
A26: Wilcoxon: RAG vs Vanilla | B26: p < 0.001 | C26: RAG značajno bolji
A27: Wilcoxon: GraphRAG vs Vanilla | B27: p < 0.001 | C27: GraphRAG značajno bolji
A30: Tablica 4. Automatske metrike (referentno, iz evaluacijske datoteke)
A31: Metrika | B31: Vanilla | C31: RAG | D31: GraphRAG
A32: ROUGE-L | B32: 0.149 | C32: 0.306 | D32: 0.279
A33: Cosine sličnost | B33: 0.898 | C33: 0.915 | D33: 0.914
A34: BERTScore | B34: 0.677 | C34: 0.723 | D34: 0.716
A35: Vrijeme (s) | B35: 34.4 | C35: 39.2 | D35: 33.5

Sheet Vanilla
A1: Detaljne ocjene po pitanju — Vanilla
A3: Rbr | B3: Kategorija | C3: Pitanje | D3: Pravna točnost | E3: Citiranje propisa | F3: Praktična primjenjivost | G3: Potpunost odgovora | H3: Jasnoća | I3: Prosjek | J3: Komentar suca | K3: Odgovor modela (Vanilla) | L3: Zlatni standard (očekivani odgovor)
A4: 1 | B4: Kompleksna – više dok. | C4: Opišite cjelokupnu proceduru transformacije novaka u razvrstanog pričuvnika kroz sve pravne akte koji reguliraju taj proces. | D4: 2 | E4: 1 | F4: 3 | G4: 3 | H4: 4 | I4: =AVERAGE(D4:H4) -> 2.6 | J4: Vanilla i Graph izmišljaju članke/tijela; RAG bliži proceduri ali nepotpun | K4: Transformacija novaka u razvrstani pričuvnik u Hrvatskoj regulirana je Zakonom o službi u Oružanim snagama Republike Hrvatske (ZSOŠ) te pripadajućim pravilnicima. Evo korak-po-korak procedure: 1. **Raspored na odsluženje vojnog roka** – Prema članku 60. ZSOŠ, mladi ljudi raspoređeni su na odsluženje vojnog roka nakon završetka srednje škole ili po drugi put kad navrše 18 godina. 2. **Proverba zdravstvenog stanja i sposobnosti** – Nakon dolaska u postrojbu, provodi se medicinska proverba kako bi se utvrdilo da li kandidat ispunjava fizičke i psihičke uvjete za služenje (članak 79. ZSOŠ). 3. **Teorijsko i praktično osposobljavanje** – Vojnici prolaze osnovno vojno osposobljavanje prema Programu vojne osposobljenosti (članak 80. ZSOŠ), uključujući topografiju, taktiku, uporabu oružja itd. 4. **Ocena sposobnosti i klasifikacija** – Na kraju osposobljavanja, zapovjednik postrojbe ocjenjuje sposobnost vojnika i daje preporuku za klasifikaciju (npr. "odlično", "dobro" itd.) (članak 81. ZSOŠ). 5. **Deklariranje kao razvrstani pričuvnik** – Ako ispuni kriterije, vojnik postaje razvrstani pričuvnik i dobiva status pričuve (članak 82. ZSOŠ). 6. **Registracija u sustavu pričuvnih snaga** – Ministarstvo obrane vodi evidenciju razvrstanih pričuvnika (članak 83. ZSOŠ). 7. **Moguća pozivnica na dodatnu osposobljavanju** – Razvrstani pričuvnici mogu biti pozvani na dodatne tečajeve ovisno o potrebama vojske (članak 84. ZSOŠ). Nadležno tijelo za ovaj postupak je Glavno stožer Oružanih snaga RH, a detaljniji uputi nalaze se u Pravilniku o provedbi ZSOŠ. | L4: Ustav RH propisuje vojnu obvezu kao dužnost svih sposobnih državljana, uz mogućnost prigovora savjesti iz vjerskih ili moralnih razloga, uz obvezu ispunjavanja drugih dužnosti određenih zakonom. Novačka obveza nastaje u kalendarskoj godini kad državljanin RH navršava 18 godina. Državljanin RH se uvodi u vojnu evidenciju i prolazi zdravstveni i psihološki pregled. Temeljno vojno osposobljavanje traje dva mjeseca. Plan upućivanja donosi ministar obrane do 15. prosinca za iduću godinu, a pojedinačna odluka 40 dana unaprijed. Ročnici se osposobljavaju za specijalnost 11A (strijelac) i polažu prisegu. Nakon temeljnog vojnog osposobljavanja ročnik automatski postaje razvrstani pričuvnik s dodijeljenim ratnim rasporedom i vojnostručnom specijalnošću. Može biti pozvan na vježbe u maksimalnom trajanju od 90 dana godišnje. Prigovor savjesti podnosi se pisanim zahtjevom nadležnom tijelu. Odobrava se osobama čija vojna služba nije spojiva s vjerskim uvjerenjima ili moralnim načelima. Umjesto vojnog osposobljavanja, obveznik ispunjava civilnu obvezu u trajanju određenom zakonom.
A5: 2 | B5: Kompleksna – više dok. | C5: Kako je regulirana hijerarhija odlučivanja o uporabi Oružanih snaga u različitim situacijama kroz Ustav i Zakon o obrani? | D5: 2 | E5: 1 | F5: 3 | G5: 2 | H5: 4 | I5: =AVERAGE(D5:H5) -> 2.4 | J5: RAG najbolje pogađa hijerarhiju; Vanilla i Graph miješaju tijela i članke | K5: Hierarhija odlučivanja o uporabi Oružanih snaga u Republici Hrvatskoj regulirana je Ustavom Republike Hrvatske (članak 97.) i Zakonom o obrani (članci 6., 8., 10.). **Prema Ustavu (čl. 97.):** - Predsjednik Republike Hrvatske vrhovni je zapovjednik Oružanih snaga. - Vlada RH ima ovlast donošenja odluka o upotrebi oružanih snaga u skladu s Ustavom i međunarodnim obvezama. **Prema Zakonu o obrani (članci 6.–10.):** - **Ministar obrane** donosi odluke o korištenju snaga pod vodstvom Vlade. - **Predsjednik RH** može rasporediti snage izvan granica samo uz suglasnost Sabora. - **Sabor RH** ima ulogu nadzora nad sigurnosnom politikom putem odbora za obranu. Nadležno tijelo za nadzor je **Državno tajništvo za nacionalnu sigurnost** (prema Pravilniku o unutarnjoj organizaciji). Napomena: Ova informacija temelji se na važećim propisima do 2024. godine. Za ažurirane podatke preporučuje se provjera najnovijih izmjena zakona. | L5: Hijerarhija odlučivanja o uporabi Oružanih snaga RH razlikuje šest situacija ovisno o razini ugroze. Ratno stanje — Predsjednik Republike naređuje uporabu i zapovijeda OS-om s punom ovlašću. Odgovoran je za obranu zemlje. Stanje neposredne ugroženosti — Predsjednik može narediti uporabu, ali odluka zahtijeva supotpis predsjednika Vlade. Prelazak granice — Sabor donosi odluku većinom svih zastupnika na prijedlog Vlade uz prethodnu suglasnost Predsjednika. Ako Predsjednik uskrati suglasnost, potrebna je dvotrećinska većina Sabora. Pomoć saveznicima — Sabor donosi odluku na prijedlog Vlade uz suglasnost Predsjednika. Vježbe i obuka — Vlada donosi odluku uz suglasnost Predsjednika. Za postrojbe do razine voda odluku donosi ministar obrane samostalno. Provedba — Načelnik Glavnog stožera ima ovlast punog zapovijedanja. Odgovoran je Predsjedniku za izvršavanje zapovijedi i naredbi, a ministru obrane za provedbu odluka.
A6: 3 | B6: Kompleksna – više dok. | C6: Objasnite sustav imenovanja i odgovornosti načelnika Glavnog stožera kroz sve relevantne propise. | D6: 2 | E6: 1 | F6: 3 | G6: 2 | H6: 4 | I6: =AVERAGE(D6:H6) -> 2.4 | J6: RAG i Graph točno: 4 god bez reizbora; Vanilla izmišlja članke i suglasnost Sabora | K6: Sustav imenovanja i odgovornosti **Načelnika Glavnog stožera OSRH** (Oružanih snaga Republike Hrvatske) reguliran je sljedećim propisima: ### **Zakon o obrani (Narodne novine br. 97/02., 86/04., 127/06.)** - **Članak 10.**: Načelnika Glavnog stožera imenuje Predsjednik Republike Hrvatske na prijedlog Vlade, uz suglasnost Sabora. - **Članak 11.**: Načelnik Glavnog stožera vrši rukovodeću funkciju u OSRH i odgovoran je za provedbu odluka Predsjednika i Vlade. ### **Zakon o službi u Oružanim snagama RH (Narodne novine br. 127/06.)** - **Članak 12.**: Načelnik Glavnog stožera ima najviši čin generala i izravno je podređen predsjedniku države kao vrhovnom zapovjedniku OSRH. ### **Pravilnik o ustroju Glavnog stožera OSRH (NN 127/06.)** - Definisan je rad Načelnika kao strateškog voditelja vojne politike i operacija. ### **Dodatne odgovornosti** - Nadzire planiranje i provedbu vojnih operacija. - Imenuje zapovjednike rodova i postrojbi po preporuci ministra obrane. - Predstavlja OSRH pred međunarodnim partnerima. Napomena: Ova informacija temelji se na važećim hrvatskim zakonima i pravilnicima do 2023. godine. Za ažurirane podatke preporučuje se provjera najnovijih izmjena. | L6: Položaj načelnika Glavnog stožera OS RH reguliran je kroz pet razina. Imenuje ga Predsjednik Republike na prijedlog Vlade, nakon pribavljenog mišljenja Odbora za obranu Sabora. Mandat traje četiri godine bez mogućnosti ponovnog imenovanja. Razrješuje ga Predsjednik Republike izravno ili na prijedlog Vlade, nakon mišljenja Odbora za obranu Sabora. Na čelu je Glavnog stožera i nadređen je svim stožerima, zapovjedništvima i postrojbama OS-a. Obnaša dužnost glavnog vojnog savjetnika Predsjedniku i ministru obrane. Ima ovlast punog zapovijedanja u OS-u. Djeluje na temelju zapovijedi Predsjednika, odluka ministra obrane i Zakona. Predsjedniku je odgovoran za provedbu zapovijedi i naredbi, a ministru obrane za provedbu odluka. Obvezan je istodobno izvještavati oba o uporabi Oružanih snaga.
A7: 4 | B7: Kompleksna – više dok. | C7: Objasnite sve oblike obveza državljana u obrani prema Zakonu o obrani i Ustavu. | D7: 2 | E7: 1 | F7: 3 | G7: 2 | H7: 4 | I7: =AVERAGE(D7:H7) -> 2.4 | J7: RAG i Graph pokrivaju vojnu/radnu/materijalnu obvezu; Vanilla izmišlja | K7: Prema **Zakonu o obrani** (Narodne novine broj 76/05) i **Ustavu Republike Hrvatske** (NN br. 123/2000), građani imaju sljedeće obveze u području obrane: 1. **Građanska obaveza prema Zakonu o obrani (čl. 8–9):** - Građani su dužni sudjelovati u obrani zemlje kroz: - **Služenje vojnog roka** (građevinski rok) – određuje se Pravilnikom o vojnom roku (NN br. 123/05). - **Mobilizaciju** – poziv na služenje u slučaju izvanrednih situacija (čl. 10). - **Dobrovoljna vojna služba** – mogućnost dobrovoljnog angažmana (čl. 11). 2. **Obveza prema Ustavu RH (čl. 14):** - Svaki građanin ima pravo i dužnost braniti domovinu. - Obrana zemlje uključuje i **alternativnu službu** za one koji iz vjerskih ili moralnih razloga ne mogu nositi oružje (čl. 14). 3. **Nadležno tijelo:** - Za provedbu zakona nadležno je **Ministarstvo obrane RH** (čl. 12 Zakona o obrani). Napomena: Ova informacija temelji se isključivo na hrvatskom zakonodavstvu. Dodatne specifikacije (npr. iznose naknada za alternativnu službu) zahtijevaju provjeru Pravilnika o vojnom roku. | L7: Vojna obveza i obrana RH dužnost je svih sposobnih državljana, uz mogućnost prigovora savjesti. Vojna obveza nastaje u godini navršenja 18 godina. Prestaje s 55 godina za muškarce odnosno 50 godina za žene. Sastoji se od novačke obveze, temeljnog vojnog osposobljavanja ili civilne službe te služenja u pričuvi. Služenje u ugovornoj pričuvi - nakon dragovoljnog vojnog osposobljavanja ili temeljnog vojnog osposobljavanje. Osposobljavanje pričuve traje do 90 dana godišnje. Radna obveza nameće se pravnim osobama i državljanima RH. Aktivira se u ratnom stanju i stanju neposredne ugroženosti. Radna pomoć se može uvesti u ratnom stanju i stanju neposredne ugroženosti radi izvršenja zadaća nositelja obrambenih funkcija. Materijalna obveza podrazumijeva ustupanje objekata i materijalnih sredstava za potrebe obrambenih zadaća i osposobljavanja.
A8: 5 | B8: Kompleksna – više dok. | C8: Kako se povezuju prigovor savjesti iz Ustava, civilna sluzba i sustav vojne obveze kroz Ustav i Zakon o obrani, i koje su posljedice odabira civilne sluzbe za status osobe? | D8: 2 | E8: 1 | F8: 3 | G8: 2 | H8: 4 | I8: =AVERAGE(D8:H8) -> 2.4 | J8: RAG i Graph točan smjer; oba dodaju netočne rokove (3/4 mj); Vanilla slabo | K8: Prema **Članku 70.** Ustava Republike Hrvatske, građani imaju pravo prigovora savjesti prema vojnoj službi, a to pravo uređuje poseban zakon. Zakon o obrani (Narodne novine 98/16) regulira priznavanje prigovora savjesti u **Članku 10.** te omogućuje zamjenu vojne službe civilnom službom. Prigovor mora biti obrazložen i dostavljen nadležnom tijelu najkasnije do početka vojne službe. Civilnu službu obavljaju građani koji nisu sposobni za vojnu službu ili odbijaju sudjelovati u oružanoj borbi zbog vjerskih, filozofskih ili moralnih uvjerenja. Trajanje civilne službe jednako je trajanju vojne službe, ali se obavlja pod nadzorom nadležnog ministarstva. Posljedice odabira civilne službe uključuju zadržavanje statusa civila, ali s ograničenjima u sudjelovanju u aktivnostima povezanim sa sigurnošću i obranom države. Osoba koja odbije vojnu službu može biti kažnjena novčanom kaznom ako ne izvrši alternativu. Nadležno tijelo za rješavanje prigovora savjesti je Ministarstvo obrane RH, a detaljnija pravila definiraju Pravilnik o priznavanju prigovora savjesti (NN 12/17). | L8: Ustav RH jamci pravo na prigovor savjesti svima koji zbog vjerskih ili moralnih nazora nisu pripravni sudjelovati u obavljanju vojnih duznosti, uz obvezu ispunjavanja drugih duznosti odredenih zakonom. Zakon o obrani tu ustavnu odredbu razraduje kroz institut vojne obveze koja nastaje u godini punoljetnosti, te propisuje da osoba s odobrenim prigovorom savjesti umjesto vojne obveze ispunjava civilnu obvezu. Posljedica je da takva osoba ne ulazi u rocnicki/pricuvni put kroz temeljno vojno osposobljavanje, nego se njezina obrambena duznost ostvaruje u nevojnom obliku, cime se ustavno nacelo (sloboda savjesti) i zakonska obveza (doprinos obrani) uskladuju.
A9: 6 | B9: Kompleksna – više dok. | C9: Objasnite cijeli put zdravstvene i psiholoske procjene novaka - od poziva do upisa u evidenciju - povezujuci Zakon o obrani s Pravilnikom o temeljnom vojnom osposobljavanju. | D9: 2 | E9: 1 | F9: 2 | G9: 2 | H9: 4 | I9: =AVERAGE(D9:H9) -> 2.2 | J9: RAG najbolje slijedi zakonski put; Graph dobar; Vanilla izmišlja testove | K9: Proces zdravstvene i psihološke procjene novaka reguliran je **Zakonom o obrani** (Narodne Novine, NN) i **Pravilnikom o temeljnom vojnom osposobljavanju** (NN). Evo koraka: 1. **Zdravstvena procjena** - Prema **Čl. 60.** Zakona o obrani, svi kandidati moraju proći medicinski pregled kako bi se utvrdilo njihovo zdravstveno stanje. - Preglede obavljaju liječnici vojne zdravstvene službe ili civilni liječnici prema kriterijima utvrđenim Pravilnikom o medicinskim pregledima (NN). 2. **Psihološka procjena** - U skladu s **Čl. 78.** Zakona o obrani, psihološka ocena provodi se radi utvrđivanja sposobnosti za služenje. - Procjenu vrši psiholog vojne zdravstvene službe prema standardiziranim testovima (npr. WAIS, Rorschach), a detalji su navedeni u **Pravilniku o psihološkoj procjeni** (NN). 3. **Evidencija i odluka** - Nakon pozitivne ocjene, kandidat se upisuje u evidenciju te započinje temeljno vojno osposobljavanje (prema **Čl. 90.** Zakona o obrani). - Neuspjesi se evidentiraju, a kandidat može biti ponovno procijenjen nakon oporavka. **Nadležno tijelo:** Vojno-medicinski centar (VMC) i psihološka služba OSRH. Napomena: Informacije su preuzete iz važećih propisa i ne uključuju specifične slučajeve iz konteksta pitanja. | L9: Zakon o obrani uspostavlja vojnu evidenciju i ovlast Ministarstva obrane da poziva obveznike, a detaljnu provedbu propisuje Pravilnik o temeljnom vojnom osposobljavanju. Po Pravilniku nadlezni podrucni odjel za poslove obrane poziva kandidata na zdravstveni pregled i psihologijsko ispitivanje, upoznaje ga s pravima i obvezama, izdaje uputnicu te osigurava prijevoz ili naknadu troskova. Kandidat se mora odazvati; u slucaju sprijecenosti duzan je u roku od tri dana obavijestiti odjel, koji odreduje novi termin. Nakon osposobljavanja nadlezna ustrojstvena jedinica u evidenciju, vojnu iskaznicu i informacijski sustav upisuje datume pocetka i zavrsetka osposobljavanja, vojnostrucnu specijalnost i datum prisege.
A10: 7 | B10: Kompleksna – više dok. | C10: Kako se nadleznost za donosenje programa obuke i provedbu svecane prisege rasporeduje izmedu ministra obrane, nacelnika Glavnog stozera i ustrojstvenih jedinica, prema Zakonu o obrani i Pravilniku o TVO? | D10: 2 | E10: 1 | F10: 2 | G10: 2 | H10: 3 | I10: =AVERAGE(D10:H10) -> 2 | J10: RAG i Graph točno o prisegi i ustrojstvenoj jedinici; Vanilla izmišlja | K10: Prema **Zakonu o obrani** (Narodne novine broj 97/06) i **Pravilniku o vojnoj vježbi i svecu prisegi** (NN broj 82/07), nadležnosti su sljedeće: 1. **Ministar obrane** ima najvišu nadležnost za donošenje **programa obuke** i odobravanje **svečane prisege** (članci 10., 11. i 12. ZOO). 2. **Nacelnik Glavnog stožera OSRH** koordinira provedbu programa obuke i nadzire ispunjavanje standarda (članak 13. ZOO). 3. **Ustrojbene jedinice** (pukovnije, zapovjedništva) provode obuku i organiziraju svečanu prisegu po odobrenim programima (članak 14. ZOO). Detaljnije odredbe nalaze se u **Pravilniku o vojnoj vježbi i svecu prisegi** (NN 82/07), poglavlje II. ("Provedba"). | L10: Plan upucivanja kandidata donosi ministar obrane (do 15. prosinca za iducu godinu, odnosno pojedinacnu odluku 40 dana prije upucivanja). Program obuke rocnika za specijalnost 11A (strijelac) donosi nacelnik Glavnog stozera, a za posebne kategorije (ugovorni pricuvnici, vojni specijalisti, kasni prijam casnika) donosi poseban program. Rocnici daju svecanu prisegu pred ministrom obrane ili osobom koju on odredi, a program prisege izraduje nadlezna ustrojstvena jedinica Ministarstva u suradnji s Glavnim stozerom. Time se zakonska razina (ministar - strateske odluke) i strucno-vojna razina (nacelnik GS - sadrzaj obuke) jasno odvajaju.
A11: 8 | B11: Kompleksna – više dok. | C11: Povezite ustavnu ulogu Predsjednika kao vrhovnog zapovjednika s lancem zapovijedanja i odgovornosti nacelnika Glavnog stozera prema Zakonu o obrani i Zakonu o sluzbi u OSRH. | D11: 3 | E11: 2 | F11: 3 | G11: 3 | H11: 4 | I11: =AVERAGE(D11:H11) -> 3 | J11: Sve tri uhvate ideju; RAG i Graph precizniji o dvostrukoj odgovornosti | K11: Prema **Zakonu o obrani** (Narodne novine br. 97/02.) i **Zakonu o službi u Oružanim snagama RH** (Narodne novine br. 86/05.), Predsjednik Republike Hrvatske ima ustavnu ulogu vrhovnog zapovjednika oružanih snaga. Međutim, operativno rukovođenje i izvršavanje zapovijedi obavlja **Nacelnik Glavnog stožera Oružanih snaga RH** (GSOS), koji je izravno odgovoran predsjedniku. ### Lanac zapovijedanja i odgovornosti: 1. **Predsjednik RH** – vrhovni zapovjednik, imenuje i razrješuje Nacelnika GSOS-a. 2. **Nacelnik GSOS-a** – najviši vojni autoritet, odgovoran za provedbu vojnih operacija i strateških odluka predsjednika. 3. **Dužnosnici u nižim stupnjevima** – izvode naredbe prema hijerarhiji. ### Pravna osnova: - **Članak 126. Ustava RH**: "Predsjednik Republike Hrvatske vrhovni je zapovjednik Oružanih snaga." - **Članak 10. Zakona o službi u OSRH**: Definisan je položaj GSOS-a kao središnjeg tijela vojne uprave. Napomena: Ova informacija temelji se na važećim zakonskim aktima Republike Hrvatske. | L11: Ustav odreduje Predsjednika RH kao vrhovnog zapovjednika Oruzanih snaga. Zakon o obrani tu ulogu operacionalizira: Predsjednik nareduje uporabu OS u ratnom stanju i odgovoran je za obranu, dok se u nizim razinama ugroze odluke dijele s Vladom i Saborom. Nacelnik Glavnog stozera ima ovlast punog zapovijedanja u provedbi, pri cemu je za izvrsavanje zapovijedi i naredbi odgovoran Predsjedniku, a ministru obrane za provedbu odluka iz njegove nadleznosti. Zakon o sluzbi dodatno ureduje status i imenovanje nacelnika unutar vojne hijerarhije. Tako se ustavno nacelo civilnog vrhovnog zapovjednistva provodi kroz dvostruku liniju odgovornosti nacelnika GS.
A12: 9 | B12: Kompleksna – više dok. | C12: Usporedite kako se pripravnost, stanje neposredne ugrozenosti i ratno stanje odrazavaju na svakodnevni rezim u postrojbi (izlasci, osiguranje objekata, uzbuna) povezujuci Zakon o obrani s Pravilnikom o sluzbi u OSRH. | D12: 2 | E12: 1 | F12: 2 | G12: 2 | H12: 3 | I12: =AVERAGE(D12:H12) -> 2 | J12: RAG dobro pokriva stupnjeve; Graph fabricira URL-ove; Vanilla generičan | K12: Prema **Zakonu o obrani** (Narodne novine broj 76/05 i izm.) te **Pravilniku o službi u Oružanim snagama RH** (NN broj 98/05), razina pripravnosti i stanja neposredne ugroženosti utječe na svakodnevni režim u postrojbama na sljedeći način: 1. **Pripravnost** – U skladu s člankom 10. Zakona, postrojbe održavaju redovitu pripravnost prema planu osmišljenom prema strateškim potrebama države. Izlaganje i osiguranje objekata odvija se prema utvrđenim rasporedima, a alarmantni postupci su definirani u članku 11. Pravilnika. 2. **Stanje neposredne ugroženosti** – Prema članku 12. Zakona, u slučaju takve situacije, zapovjednik može donijeti odluke o povećanju sigurnosnih mjera, uključujući ograničavanje kretanja osoblja ili pojačano osiguranje ključnih objekata. Pravilnik to detaljnije regulira u poglavlju V., točku 2. 3. **Ratno stanje** – Prema članku 13. Zakona, u ratu postrojbe ulaze u punu operativnu spremnost, s aktivacijom svih snaga i sredstava. Pravilnik to dodatno precizira u članku 14., gdje su definirani postupci za mobilizaciju i djelovanje pod zračnom opasnošću. Dodatno, prema članku 15. Pravilnika, zapovjednici postrojbi imaju ovlast prilagođavati dnevni red ovisno o stupnju ugroženosti, što uključuje i provođenje vježbi za brzo reagiranje. *Napomena: Ova informacija temelji se na analizi relevantnog zakonodavstva i ne sadrži konkretan kontekst iz upita. | L12: Zakon o obrani definira stupnjeve ugroze i tijela koja ih proglasavaju, a Pravilnik o sluzbi razraduje njihove operativne posljedice. Pri pripravnosti, stanju neposredne ugrozenosti ili ratnom stanju osiguranje objekata se pojacava (vise osoba, tehnicka i inzenjerijska sredstva), redoviti i izvanredni izlasci vojnih osoba ogranicavaju se ili obustavljaju, a privatna putovanja se obustavljaju kada je zapovjedena pripravnost. Uzbuna (borbena, mobilizacijska, zbog nesreca, radi provjere) dovodi postrojbu na trazeni stupanj spremnosti prikupljanjem na mjestima za uzbunu. Tako se pravni okvir (Zakon) preslikava u konkretne dnevne duznosti (Pravilnik).
A13: 10 | B13: Kompleksna – više dok. | C13: Objasnite cijeli zivotni ciklus ugovornog odnosa vojnika/mornara - od prijma do rasporeda na ustrojbeno mjesto - povezujuci ustavnu osnovu vojne sluzbe sa Zakonom o sluzbi u OSRH. | D13: 2 | E13: 1 | F13: 3 | G13: 2 | H13: 4 | I13: =AVERAGE(D13:H13) -> 2.4 | J13: RAG i Graph točni uvjeti prijma; Vanilla izmišlja ustavni članak | K13: Životni ciklus ugovornog odnosa vojnika ili mornara u Oružanim snagama Republike Hrvatske (OSRH) reguliran je Ustavom RH, Zakonom o službi u OSRH te pripadajućim pravilnicima. Evo detaljnog pregleda: ### **1. Prijam na vojnu službu** - **Ustavna osnova**: Članak 80. Ustava RH uređuje pravo na vojnu službu, dok Zakon o službi u OSRH (čl. 6.) definira uvjete za pristup vojsci. - **Postupak**: Kandidat potpisuje **ugovor o radu u OSRH** (čl. 7. ZSOSRH), koji uključuje rok trajanja (obično 5 godina s mogućnošću produženja). - **Pregledi i ocjene**: Provjeravaju se zdravstveno stanje, psihofizička sposobnost i vojna sprema (čl. 9. ZSOSRH). ### **2. Razvrstavanje i ustrojavanje** - Nakon primopredaje, vojnik/mornar dobiva **ustrojbeno mjesto** prema stručnoj spremi (npr. topnik, vozač, medicinski tehničar – čl. 12. ZSOSRH). - **Dodatne kvalifikacije**: Po završetku škole za časnike ili specijalizirane programe (čl. 14. ZSOSRH). ### **3. Služenje i napredovanje** - Vojnici/mornari prolaze kroz stupnjeve po činu (svjedok, narednik, potporučnik itd., čl. 16. ZSOSRH). - Nagrade i sankcije regulirani su Pravilnikom o disciplinskoj odgovornosti (NN 121/10). ### **4. Kraj službe** - Raskid ugovora može biti sporazuman (čl. 21. ZSOSRH) ili zbog povrede obveza. | L13: Ustav RH postavlja vojnu obvezu i sudjelovanje u obrani kao duznost drzavljana, a Zakon o sluzbi tu osnovu razraduje u konkretan ugovorni put. Prijam vojnika/mornara provodi se prema godisnjem planu prijma, uz mogucnost dodatnih kriterija ovisno o rodu, sluzbi i vojnostrucnoj specijalnosti, te kroz odabirni postupak propisan posebnim pravilnikom. Odnos se zasniva ugovorom o vojnickoj sluzbi. Nakon prijma djelatnu vojnu osobu imenuje se na duznost odnosno rasporeduje na ustrojbeno mjesto u skladu s uvjetima tog mjesta, cinom i stecenom vojnostrucnom specijalnosti; raspored na mjesto za koje je propisana opca specijalnost smatra se odgovarajucim. Tako se ustavno nacelo doprinosa obrani pretvara u ureden, ugovorom vezan i specijalnoscu uskladen radni status.
A14: 11 | B14: Kompleksna – više dok. | C14: Kako se prava rocnika tijekom temeljnog vojnog osposobljavanja (placa, osiguranje, prijevoz) povezuju s opcim rezimom sluzbe - objasnite kroz Pravilnik o TVO, Zakon o sluzbi i Pravilnik o sluzbi u OSRH. | D14: 2 | E14: 1 | F14: 3 | G14: 2 | H14: 3 | I14: =AVERAGE(D14:H14) -> 2.2 | J14: RAG i Graph točno navode čl.18 i čl.137; Vanilla izmišlja NN brojeve | K14: Temeljno vojno osposobljavanje (TVO) regrūtā koji sklapaju ugovor o službi u Oružanim snagama Republike Hrvatske (OSRH) regulirano je Pravilnikom o temeljnom vojnom osposobljavanju (Narodne novine br. 97/06), Zakonom o službi u Oružanim snagama Republike Hrvatske (NN 82/07) te Pravilnikom o službi u Oružanim snagama Republike Hrvatske (NN 110/07). ### **Plaća** Regrūtī imaju pravo na plaću od trenutka stupanja u službu do završetka TVO-a (čl. 12 Pravilnika o TVO). Plaća se isplaćuje mjesečno prema stupnju i dužnosti (čl. 13 Zakona o službi). ### **Osiguranje** Tijekom TVO-a regrūtī su osigurani prema sustavu zdravstvenog osiguranja OSRH (čl. 14 Pravilnika o TVO). U slučaju ozljede ili bolesti, skrba je osigurana prema propisima o zdravstvenoj skrbi u OSRH (čl. 15 Zakona o službi). ### **Prijevoz** Regrūtī imaju pravo na besplatan prijevoz do mjesta osposobljavanja i natrag ako to zahtijeva službeno zaduživanje (čl. 16 Pravilnika o TVO). Prijevoz se organizira putem sredstava OSRH. Ovi uvjeti vrijede isključivo za razdoblje TVO-a, a daljnja prava i obveze ovise o vrsti ugovora (časnička, profesionalna ili pričuvnička služba) i stupnju službe. Za detalje pogledajte odgovarajuće članke navedenih propisa. *Napomena: Ova informacija temelji se na općem znanju o hrvatskom vojnom zakonu. | L14: Pravilnik o TVO utvrduje da rocnik za vrijeme osposobljavanja ostvaruje pravo na placu odnosno naknadu u iznosu odredenom zakonom kojim se ureduje sluzba (dakle upucuje na Zakon o sluzbi), naknadu troskova javnog prijevoza, osnovno i dopunsko zdravstveno osiguranje, osiguranje od nesretnog slucaja i ozljede na radu, smjestaj, prehranu te odoru i sportsku opremu. Pritom Pravilnik o TVO izrijekom propisuje da se zivot i rad rocnika provodi u skladu s propisima o sluzbi u Oruzanim snagama - cime se na rocnika primjenjuje opci rezim dnevnih aktivnosti, izlazaka i unutarnje sluzbe iz Pravilnika o sluzbi u OSRH. Time se posebni status rocnika (TVO) i opci rezim pripadnika OS spajaju u jedinstven pravni okvir.
A15: 12 | B15: Kompleksna – više dok. | C15: Objasnite kako su sloboda vjeroispovijedi i rad dusobriznika uredeni od ustavne razine do svakodnevne provedbe u postrojbi, povezujuci Ustav, Pravilnik o sluzbi u OSRH i raspored dnevnih aktivnosti. | D15: 3 | E15: 2 | F15: 3 | G15: 2 | H15: 4 | I15: =AVERAGE(D15:H15) -> 2.8 | J15: Graph i Vanilla pogode čl.40; RAG pobrka pojam dragovoljaca | K15: Sloboda vjeroispovijedi u Republici Hrvatskoj zajamčena je **Člankom 40.** Ustava RH, prema kojem svatko ima pravo na slobodno ispovijedanje vjere i javno izražavanje svojih uvjerenja. ### **Upravljanje vjerskim potrebama vojnika (Dušebrižnička služba):** 1. **Zakonska osnova:** - **Zakon o službi u OSRH (čl. 87.)** predviđa pružanje duhovne skrbi vojnicima, uključujući mogućnost posjeta dušobrižnika. - **Pravilnik o organizaciji i načinu obavljanja službe u OSRH (NN 9/16)** detaljno regulira provođenje vjerskih potreba, uključujući rasporede bogoslužja i suradnju s crkvama. 2. **Dnevni raspored i provedba:** - Vojnici mogu zatražiti duhovnu pomoć putem zapovjednog lanca ili direktno kod kapelana. - Dušobrižnička služba organizira tjedne mise, svetkovice i druge vjerske događaje prema crkvenom kalendaru. - Vojnici različitih vjera imaju pravo na privatno molitveno vrijeme unutar dopuštenih sati. 3. **Nadležno tijelo:** - Za katoličku vjeru: Biskupski ordinarijat i Vojni ordinarijat RH. - Za ostale vjere: Koordinacija sa službenim predstavnicima pojedinih zajednica. Napomena: Informacije se temelje na važećim propisima i praksi u OSRH. Slobodna vjeroispovijest uključuje i poštovanje sekularnosti postrojbe, gdje se vjerski simboli ne ističu u službenoj uniformi osim ako to dozvoljavaju pravila određene vjere. | L15: Ustav RH jamci slobodu savjesti i vjeroispovijedi te slobodno javno ocitovanje vjere. Pravilnik o sluzbi u OSRH tu slobodu prenosi u vojni kontekst: pripadnicima se jamci sloboda vjeroispovijedi i slobodno javno ocitovanje vjerskog ili drugog uvjerenja, izrijekom se zabranjuje vrijedanje i poruga na toj osnovi, a dusobriznici svojim radom pridonose domoljublju te vjerskoj ravnopravnosti i snosljivosti. Na operativnoj razini, rad dusobriznika - predstavnika vjerskih zajednica uvrstava se u raspored dnevnih aktivnosti, u skladu s ugovorima i protokolima sklopljenima s vjerskim zajednicama. Tako ustavno pravo dobiva konkretan vremenski i organizacijski okvir unutar postrojbe.
... A46: 43 | B46: Jednostavna | C46: Što je vojna iskaznica i tko ju izdaje? | D46: 2 | E46: 1 | F46: 3 | G46: 2 | H46: 4 | I46: =AVERAGE(D46:H46) -> 2.4 | J46: RAG najbliži (javna isprava, područni odjel); Graph i Vanilla djelomično | K46: Vojna iskaznica (VI) je osobna iskaznica vojnog obveznika koja potvrđuje njegovo pravo na služenje vojne službe te sadrži podatke o obveznim vojnim rokovanjima i statusu u sustavu Oružanih snaga Republike Hrvatske. **Izdaje se od strane Ministarstva obrane RH** putem nadležnih jedinica, a to su: - **Zapovjedništva postrojbi** (npr. pješačke brigade, topničke brigade itd.) - **Regionalni centri za obuku i mobilizaciju** - **Središnja uprava MORH-a** (za posebne slučajeve) Iskaznica se izdaju nakon prijave na vojni rok ili u slučaju poziva na osposobljavanje/mobilizaciju. Za dodatne informacije pogledajte **Zakon o službi u Oružanim snagama RH (čl. 8–9)** i Pravilnik o vojnoj iskaznici (NN br. 107/20 od 2020.). | L46: Vojna iskaznica je javna isprava kojom vojni obveznik dokazuje identitet dok izvršava vojnu obvezu. Izdaje ju nadležni područni odjel za poslove obrane koji vojnog obveznika vodi u evidenciji.
C47: PROSJEK | D47: =AVERAGE(D4:D46) -> 2.1627907 | E47: =AVERAGE(E4:E46) -> 1.372093 | F47: =AVERAGE(F4:F46) -> 2.9069767 | G47: =AVERAGE(G4:G46) -> 2.3023256 | H47: =AVERAGE(H4:H46) -> 3.6744186 | I47: =AVERAGE(I4:I46) -> 2.4837209

Sheet RAG
A1: Detaljne ocjene po pitanju — RAG
A3: Rbr | B3: Kategorija | C3: Pitanje | D3: Pravna točnost | E3: Citiranje propisa | F3: Praktična primjenjivost | G3: Potpunost odgovora | H3: Jasnoća | I3: Prosjek | J3: Komentar suca | K3: Odgovor modela (RAG) | L3: Zlatni standard (očekivani odgovor)
A4: 1 | B4: Kompleksna – više dok. | C4: Opišite cjelokupnu proceduru transformacije novaka u razvrstanog pričuvnika kroz sve pravne akte koji reguliraju taj proces. | D4: 3 | E4: 3 | F4: 4 | G4: 3 | H4: 4 | I4: =AVERAGE(D4:H4) -> 3.4 | J4: Vanilla i Graph izmišljaju članke/tijela; RAG bliži proceduri ali nepotpun | K4: Transformacija novaka u razvrstanog pričuvnika regulirana je Zakonom o obrani 2025. Ovaj proces uključuje nekoliko ključnih koraka: 1. **Ocjena sposobnosti** *(Članak 25. d, NN 136/25)* - Kada dođe do promjene zdravstvenog stanja, nadležni područni odjel za poslove obrane upućuje razvrstanog pričuvnika na ocjenu sposobnosti. - Ocjenu donosi nadležna liječnička komisija na temelju zdravstvene dokumentacije. - Ako dokumentacija nije dovoljna, traži se dodatna dokumentacija. - Rezultat se unosi u vojnu iskaznicu. 2. **Dodjela vojne stručne specijalnosti** *(Članak 25. k, NN 136/25)* - Prema utvrđenom zdravstvenom stanju i potrebama OSRH-a, može se odrediti drugi rod ili struka. 3. **Registracija u vojnu evidenciju** *(Članak 21. h, NN 136/25)* - Nakon ocjene sposobnosti, osoba se upisuje u evidenciju. - Ako je ocijenjena nesposobnom, moguće je pozvati na reviziju. 4. **Suradnja s diplomatskim tijelima** *(Članak 21. c, NN 136/25)* - Novi koji borave u inozemstvu moraju se registrirati do 18. godine života. - Oni izvan sustava mogu to učiniti do 29. godine. - Potreban je certifikat države u kojoj je obveza izvršena. 5. **Programiranje osposobljavanja** *(Članak 25. j, NN 136/25)* - Nakon pozitivne ocjene, priključuje se na programe osposobljavanja. - Termini se određuju prema potrebama OSRH-a. 6. **Upisivanje u pričuvni sustav** *(Članak 25. r, NN 136/25)* - Neispunjenje roka dovršetka osposobljavanja vraća osobu u status novaka. Proces se temelji na koordinaciji između Ministarstva obrane, liječničkih komisija i diplomatskih predstavništava. Ključni dokumenti uključuju: - Vojnu iskaznicu - Evidenciju ročnika i pričuvnika *(Zakon o službi u OSRH 2025, Članak 32.)* - Pravilnike o zdravstvenim pregledima i osposobljavanju. Napomena: Postupak se primjenjuje isključivo na državljane RH i one s prebivalištem u zemlji. Inozemni državljani imaju poseban režim prema članku 21. | L4: Ustav RH propisuje vojnu obvezu kao dužnost svih sposobnih državljana, uz mogućnost prigovora savjesti iz vjerskih ili moralnih razloga, uz obvezu ispunjavanja drugih dužnosti određenih zakonom. Novačka obveza nastaje u kalendarskoj godini kad državljanin RH navršava 18 godina. Državljanin RH se uvodi u vojnu evidenciju i prolazi zdravstveni i psihološki pregled. Temeljno vojno osposobljavanje traje dva mjeseca. Plan upućivanja donosi ministar obrane do 15. prosinca za iduću godinu, a pojedinačna odluka 40 dana unaprijed. Ročnici se osposobljavaju za specijalnost 11A (strijelac) i polažu prisegu. Nakon temeljnog vojnog osposobljavanja ročnik automatski postaje razvrstani pričuvnik s dodijeljenim ratnim rasporedom i vojnostručnom specijalnošću. Može biti pozvan na vježbe u maksimalnom trajanju od 90 dana godišnje. Prigovor savjesti podnosi se pisanim zahtjevom nadležnom tijelu. Odobrava se osobama čija vojna služba nije spojiva s vjerskim uvjerenjima ili moralnim načelima. Umjesto vojnog osposobljavanja, obveznik ispunjava civilnu obvezu u trajanju određenom zakonom.
A5: 2 | B5: Kompleksna – više dok. | C5: Kako je regulirana hijerarhija odlučivanja o uporabi Oružanih snaga u različitim situacijama kroz Ustav i Zakon o obrani? | D5: 3 | E5: 3 | F5: 4 | G5: 3 | H5: 4 | I5: =AVERAGE(D5:H5) -> 3.4 | J5: RAG najbolje pogađa hijerarhiju; Vanilla i Graph miješaju tijela i članke | K5: Prema Ustavu Republike Hrvatske (Članak 100.) i Zakonu o obrani (Članak 46.), hijerarhija odlučivanja o uporabi Oružanih snaga u različitim situacijama je sljedeća: 1. **U ratu** – Prema Ustavu (Članak 100., stavak 5.) i Zakonu o obrani (Članak 47.), odluku o uporabi Oružanih snaga donosi Predsjednik Republike. 2. **U stanju neposredne ugroženosti** – Prema Ustavu (Članak 100., stavak 5.) i Zakonu o obrani (Članci 48. i 63.), odluku donose Predsjednik Republike uz supotpis predsjednika Vlade. 3. **U ostalim slučajevima** – Prema Zakonu o obrani (Članak 48., stavak 2.), odluku donosi Vlada ili ministar obrane. Detaljnije: - **Predsjednik Republike** ima najvišu nadležnost u donošenju odluka o uporabi Oružanih snaga (Ustav, Članak 100.). - **Vlada** i **ministar obrane** također sudjeluju u donošenju odluka, ovisno o situaciji (Zakon o obrani, Članak 48., stavak 2.). - **Stalni mehanizam provedbe** – Sve odluke se izvršavaju putem zapovijedi načelnika Glavnog stožera (Zakon o obrani, Članak 46., stavak 3.). Napomena: Ova struktura vrijedi osim u izvanrednim situacijama gdje Predsjednik Republike može djelovati autonomnije (npr. prema Ustavu, Članak 100., stavak 5.). | L5: Hijerarhija odlučivanja o uporabi Oružanih snaga RH razlikuje šest situacija ovisno o razini ugroze. Ratno stanje — Predsjednik Republike naređuje uporabu i zapovijeda OS-om s punom ovlašću. Odgovoran je za obranu zemlje. Stanje neposredne ugroženosti — Predsjednik može narediti uporabu, ali odluka zahtijeva supotpis predsjednika Vlade. Prelazak granice — Sabor donosi odluku većinom svih zastupnika na prijedlog Vlade uz prethodnu suglasnost Predsjednika. Ako Predsjednik uskrati suglasnost, potrebna je dvotrećinska većina Sabora. Pomoć saveznicima — Sabor donosi odluku na prijedlog Vlade uz suglasnost Predsjednika. Vježbe i obuka — Vlada donosi odluku uz suglasnost Predsjednika. Za postrojbe do razine voda odluku donosi ministar obrane samostalno. Provedba — Načelnik Glavnog stožera ima ovlast punog zapovijedanja. Odgovoran je Predsjedniku za izvršavanje zapovijedi i naredbi, a ministru obrane za provedbu odluka.
A6: 3 | B6: Kompleksna – više dok. | C6: Objasnite sustav imenovanja i odgovornosti načelnika Glavnog stožera kroz sve relevantne propise. | D6: 4 | E6: 4 | F6: 4 | G6: 4 | H6: 4 | I6: =AVERAGE(D6:H6) -> 4 | J6: RAG i Graph točno: 4 god bez reizbora; Vanilla izmišlja članke i suglasnost Sabora | K6: Sustav imenovanja i odgovornosti **načelnika Glavnog stožera** uređen je sljedećim propisima: ### **1. Imenovanje načelnika Glavnog stožera** - Prema **Članku 16. stavku 4. Zakona o obrani (2025.)**, **načelnik Glavnog stožera imenuje se na razdoblje od četiri godine i ne može biti ponovno imenovan**. - **Članak 123.** istog zakona navodi da osoba koja je na dužnosti načelnika Glavnog stožera na dan stupanja na snagu Zakona ostaje na dužnosti do isteka svog mandata. - **Propisivanje ustroja Glavnog stožera** vrši Predsjednik Republike na prijedlog načelnika Glavnog stožera i uz suglasnost ministra obrane (**Članak 16. stavak 5.**). ### **2. Nadležnosti i odgovornosti načelnika Glavnog stožera** - Prema **Članku 70.** Zakona o obrani, načelnik Glavnog stožera ima **punu ovlast zapovijedanja u Oružanim snagama** temeljem odluka Predsjednika Republike i ministra obrane. - Dužan je **istodobno izvijestiti predsjednika i ministra** ako naredi privremeno stavljanje postrojbi u pripravnost zbog opasnosti (**Članak 70. stavak 4.**). - Prema **Članku 67.**, ministar obrane na prijedlog načelnika Glavnog stožera donosi odluke o opremanju, obuci i spremnosti dijelova Oružanih snaga. - Prema **Članku 75.**, načelnik Glavnog stožera odgovoran je za pripremu mobilizacije stožera, zapovjedništava i postrojbi. ### **3. Pravni okvir i nadzor** - Iako Ustav (**Članak 103.**) ne spominje izravno načelnika Glavnog stožera, predviđa suradnju Predsjednika i Vlade u sigurnosnim pitanjima. - Prema **Članku 51.** Zakona o službi u Oružanim snagama, ministar obrane raspoređuje djelatne vojne osobe na ustrojbena mjesta, uključujući i one koje imenuje Predsjednik. ### **Zaključak** Načelnik Glavnog stožera bira se na mandat od 4 godine, ima široke zapovjedne ovlasti potvrđene predsjednikom i ministrom obrane, ali ne može biti reizabran. Njegova djelokrug uključuje strateško upravljanje Oružanim snagama, mobilizaciju i koordinaciju s najvišim državnim tijelima. | L6: Položaj načelnika Glavnog stožera OS RH reguliran je kroz pet razina. Imenuje ga Predsjednik Republike na prijedlog Vlade, nakon pribavljenog mišljenja Odbora za obranu Sabora. Mandat traje četiri godine bez mogućnosti ponovnog imenovanja. Razrješuje ga Predsjednik Republike izravno ili na prijedlog Vlade, nakon mišljenja Odbora za obranu Sabora. Na čelu je Glavnog stožera i nadređen je svim stožerima, zapovjedništvima i postrojbama OS-a. Obnaša dužnost glavnog vojnog savjetnika Predsjedniku i ministru obrane. Ima ovlast punog zapovijedanja u OS-u. Djeluje na temelju zapovijedi Predsjednika, odluka ministra obrane i Zakona. Predsjedniku je odgovoran za provedbu zapovijedi i naredbi, a ministru obrane za provedbu odluka. Obvezan je istodobno izvještavati oba o uporabi Oružanih snaga.
A7: 4 | B7: Kompleksna – više dok. | C7: Objasnite sve oblike obveza državljana u obrani prema Zakonu o obrani i Ustavu. | D7: 4 | E7: 3 | F7: 4 | G7: 4 | H7: 4 | I7: =AVERAGE(D7:H7) -> 3.8 | J7: RAG i Graph pokrivaju vojnu/radnu/materijalnu obvezu; Vanilla izmišlja | K7: Prema **Zakonu o obrani** i **Ustavu Republike Hrvatske**, građani imaju različite oblike obveza u obrani: ### 1. **Vojna obveza** - Prema **Čl. 19.** Zakona o obrani, vojna obveza počinje kalendarskom godinom u kojoj građanin navrši 18 godina. - Građani su dužni proći osposobljavanje i sudjelovati u obrani (**Čl. 18., Stavak 1.**). - Dopušten je prigovor savjesti zbog vjerskih ili moralnih razloga (**Ustav, Čl. 47.**). ### 2. **Radna obveza** - Prema **Čl. 29.** Zakona o obrani, Vlada može uvesti radnu obvezu za tijela državne vlasti i pravne osobe važne za obranu. - Osobe s radnom obvezom ne smiju prekinuti posao i moraju raditi prema ratnim sistematizacijama (**Čl. 29., Stavak 3.**). - Trudnice, majke i skrbnici s malom djecom izuzeti su (**Čl. 29., Stavak 5.**). ### 3. **Materijalna obveza** - Građani su dužni pružiti materijalnu potporu (npr. financijska sredstva, opskrba) za potrebe obrane (**Čl. 18., Stavak 6.**). ### 4. **Služenje u ugovornoj pričuvi** - Pričuvnici sklapaju ugovore za služenje u Oružanim snagama (**Čl. 18., Stavak 2.**). ### 5. **Radna pomoć** - Prema **Čl. 31.** Zakona o obrani, Vlada može uvesti radnu pomoć u ratu ili neposrednoj ugrozi. ### 6. **Ostala prava i obveze** - Građani imaju pravo na zaštitu i sudjelovanje u obrani putem drugih mehanizama (**Čl. 18., Stavak 7.**). Ove obveze pokrivaju sve aspekte sudjelovanja građana u obrani, od aktivnog služenja do pasivnih potpore. Nadležna tijela uključuju Vladu, Ministarstvo obrane i jedinice lokalne samouprave. | L7: Vojna obveza i obrana RH dužnost je svih sposobnih državljana, uz mogućnost prigovora savjesti. Vojna obveza nastaje u godini navršenja 18 godina. Prestaje s 55 godina za muškarce odnosno 50 godina za žene. Sastoji se od novačke obveze, temeljnog vojnog osposobljavanja ili civilne službe te služenja u pričuvi. Služenje u ugovornoj pričuvi - nakon dragovoljnog vojnog osposobljavanja ili temeljnog vojnog osposobljavanje. Osposobljavanje pričuve traje do 90 dana godišnje. Radna obveza nameće se pravnim osobama i državljanima RH. Aktivira se u ratnom stanju i stanju neposredne ugroženosti. Radna pomoć se može uvesti u ratnom stanju i stanju neposredne ugroženosti radi izvršenja zadaća nositelja obrambenih funkcija. Materijalna obveza podrazumijeva ustupanje objekata i materijalnih sredstava za potrebe obrambenih zadaća i osposobljavanja.
A8: 5 | B8: Kompleksna – više dok. | C8: Kako se povezuju prigovor savjesti iz Ustava, civilna sluzba i sustav vojne obveze kroz Ustav i Zakon o obrani, i koje su posljedice odabira civilne sluzbe za status osobe? | D8: 3 | E8: 2 | F8: 3 | G8: 3 | H8: 4 | I8: =AVERAGE(D8:H8) -> 3 | J8: RAG i Graph točan smjer; oba dodaju netočne rokove (3/4 mj); Vanilla slabo | K8: Prema Ustavu Republike Hrvatske (Članak 47.), vojna obveza i obrana države jesu dužnost svih građana, no dopušten je prigovor savjesti onima koji zbog vjerskih ili moralnih uvjerenja ne žele sudjelovati u obavljanju vojničkih dužnosti u Oružanim snagama. Takve osobe moraju ispunjavati druge dužnosti određene zakonom. Zakon o obrani (Članak 24.) detaljnije uređuje ovaj institut. Prema njemu, osobe koje podnose prigovor savjesti imaju pravo na civilnu službu umjesto vojne. Trajanje civilne službe iznosi tri mjeseca u tijelima državne uprave nadležnim za civilnu zaštitu. Međutim, postoje i iznimke kada se civilna služba može obavljati u jedinicama lokalne i područne (regionalne) samouprave, a traje četiri mjeseca. Posljedice odabira civilne službe uključuju sljedeće: - Osoba postaje civilni ročnik od dana dolaska u tijelo nadležno za civilnu zaštitu. - Dužna je ispunjavati sve obveze propisane zakonom vezano za civilnu službu. - Nakon isteka roka civilne službe, osoba se vraća u redovni život, a njezin status se ne razlikuje značajno od onih koji su odslužili vojnu službu. Isključeni su iz mogućnosti odabira civilne službe oni koji su pravomoćno osuđeni na kazne zatvora, imaju kaznene prijave u tijeku ili posjeduju oružje bez dozvole. Također, osoba koja promijeni mišljenje i želi sudjelovati u vojnoj službi može biti upućena na osnovno vojno osposobljavanje. Civilna služba predstavlja alternativu vojnoj obvezi, omogućavajući građanima poštivanje ustavnog prava na prigovor savjesti, istovremeno pridonoseći zajednici kroz rad u području civilne zaštite. | L8: Ustav RH jamci pravo na prigovor savjesti svima koji zbog vjerskih ili moralnih nazora nisu pripravni sudjelovati u obavljanju vojnih duznosti, uz obvezu ispunjavanja drugih duznosti odredenih zakonom. Zakon o obrani tu ustavnu odredbu razraduje kroz institut vojne obveze koja nastaje u godini punoljetnosti, te propisuje da osoba s odobrenim prigovorom savjesti umjesto vojne obveze ispunjava civilnu obvezu. Posljedica je da takva osoba ne ulazi u rocnicki/pricuvni put kroz temeljno vojno osposobljavanje, nego se njezina obrambena duznost ostvaruje u nevojnom obliku, cime se ustavno nacelo (sloboda savjesti) i zakonska obveza (doprinos obrani) uskladuju.
A9: 6 | B9: Kompleksna – više dok. | C9: Objasnite cijeli put zdravstvene i psiholoske procjene novaka - od poziva do upisa u evidenciju - povezujuci Zakon o obrani s Pravilnikom o temeljnom vojnom osposobljavanju. | D9: 4 | E9: 4 | F9: 4 | G9: 4 | H9: 4 | I9: =AVERAGE(D9:H9) -> 4 | J9: RAG najbolje slijedi zakonski put; Graph dobar; Vanilla izmišlja testove | K9: Prema Zakonu o obrani (NN 136/25), članku 21. točki f, novačka obveza započinje kalendarskom godinom u kojoj građanin Republike Hrvatske navršava 18 godina života. U tom trenutku, nadležni područni odjel za poslove obrane poziva novaka na zdravstveni pregled i psihologijsko ispitivanje, kako je definirano u planu koji donosi ustrojstvena jedinica Ministarstva obrane nadležna za vojnu obvezu (članak 21. točka g). Na temelju rezultata tih ispita, ocjenjuje se sposobnost novaka za vojnu službu kao **sposoban** ili **nesposoban** (članak 21. točka 4). Ako je novak ocijenjen nesposobnim, ne šalje se na daljnje aktivnosti (članak 21. točka 2). S druge strane, ako je sposoban, upisuje se u vojnu evidenciju i može biti pozvan na temeljno vojno osposobljavanje (članak 21. točke h i n). Temeljno vojno osposobljavanje provodi se u skladu s planom koji donosi ministar obrane (članak 21. točka m), a traje dva mjeseca (članak 21. točka n). Nakon završetka, sposobni novaci dobivaju status ročnika i mogu nastaviti službu u pričuvnom sastavu (članak 21. točka p). Za dodatne detalje o postupcima i pravilnicima, potrebno je proučavati Pravilnik o temeljnom vojnom osposobljavanju, koji dodatno regulira procedure zdravstvenih i psiholoških procjena. Međutim, Zakon o obrani već sadrži ključne odredbe vezane za ovaj proces. Napomena: Informacije o Pravilniku o temeljnom vojnom osposobljavanju nisu uključene u dostupne dokumente. | L9: Zakon o obrani uspostavlja vojnu evidenciju i ovlast Ministarstva obrane da poziva obveznike, a detaljnu provedbu propisuje Pravilnik o temeljnom vojnom osposobljavanju. Po Pravilniku nadlezni podrucni odjel za poslove obrane poziva kandidata na zdravstveni pregled i psihologijsko ispitivanje, upoznaje ga s pravima i obvezama, izdaje uputnicu te osigurava prijevoz ili naknadu troskova. Kandidat se mora odazvati; u slucaju sprijecenosti duzan je u roku od tri dana obavijestiti odjel, koji odreduje novi termin. Nakon osposobljavanja nadlezna ustrojstvena jedinica u evidenciju, vojnu iskaznicu i informacijski sustav upisuje datume pocetka i zavrsetka osposobljavanja, vojnostrucnu specijalnost i datum prisege.
A10: 7 | B10: Kompleksna – više dok. | C10: Kako se nadleznost za donosenje programa obuke i provedbu svecane prisege rasporeduje izmedu ministra obrane, nacelnika Glavnog stozera i ustrojstvenih jedinica, prema Zakonu o obrani i Pravilniku o TVO? | D10: 4 | E10: 4 | F10: 4 | G10: 3 | H10: 4 | I10: =AVERAGE(D10:H10) -> 3.8 | J10: RAG i Graph točno o prisegi i ustrojstvenoj jedinici; Vanilla izmišlja | K10: Prema Zakonu o obrani i Pravilniku o temeljnom vojnom osposobljavanju (TVO), nadležnost za donošenje programa obuke i provedbu svečane prisege raspodijeljena je kako slijedi: 1. **Program svečane prisege**: - Prema članku 10. Pravilnika o TVO, **program svečane prisege** izrađuje **nadležna ustrojstvena jedinica Ministarstva obrane** u suradnji s Glavnim stožerom OS RH. - Dakle, glavni zadatak izrade programa leži na ustrojstvenim jedinicama MORH-a, uz koordinaciju Glavnog stožera. 2. **Donošenje programa obuke**: - Iako Pravilnik o TVO ne sadrži direktan članak o donošenju programa obuke, članak 82. Zakona o obrani nalaže da **ministar obrane** odlukom utvrđuje: - Vrste, sadržaj, način, uvjete, vrijeme i nositelje osposobljavanja. - Prema članku 79. Zakona o službi u OS RH, **načelnik Glavnog stožera** može donositi pravilnike o vojnoj obuki (npr. za pričuvne dočasnike). - Tako se nadležnost dijeli između ministra (strateški okvir) i Glavnog stožera (tehnička provedba). 3. **Provedba svečane prisege**: - Stavak 1. članka 10. Pravilnika o TVO nalaže da ročnici polažu prisegu **pred ministrom obrane ili osobom koju on odredi**. - To znači da ministar ima krajnju nadležnost za ovaj ceremonijalni akt. ### Sažeto: - **Program svečane prisege**: Ustrojstvene jedinice MORH-a (čl. 10. Pravilnika o TVO). - **Donošenje programa obuke**: Ministar obrane (čl. 82. Zakona o obrani) + načelnik GS (čl. 79. Zakona o službi). - **Provedba svečane prisege**: Ministar obrane (čl. 10. Pravilnika o TVO). Napomena: Ako se radi o specijaliziranoj obradi (npr. za pričuve), dodatno se primjenjuju članci 79. i 82. Zakona o službi. | L10: Plan upucivanja kandidata donosi ministar obrane (do 15. prosinca za iducu godinu, odnosno pojedinacnu odluku 40 dana prije upucivanja). Program obuke rocnika za specijalnost 11A (strijelac) donosi nacelnik Glavnog stozera, a za posebne kategorije (ugovorni pricuvnici, vojni specijalisti, kasni prijam casnika) donosi poseban program. Rocnici daju svecanu prisegu pred ministrom obrane ili osobom koju on odredi, a program prisege izraduje nadlezna ustrojstvena jedinica Ministarstva u suradnji s Glavnim stozerom. Time se zakonska razina (ministar - strateske odluke) i strucno-vojna razina (nacelnik GS - sadrzaj obuke) jasno odvajaju.
A11: 8 | B11: Kompleksna – više dok. | C11: Povezite ustavnu ulogu Predsjednika kao vrhovnog zapovjednika s lancem zapovijedanja i odgovornosti nacelnika Glavnog stozera prema Zakonu o obrani i Zakonu o sluzbi u OSRH. | D11: 4 | E11: 3 | F11: 4 | G11: 4 | H11: 4 | I11: =AVERAGE(D11:H11) -> 3.8 | J11: Sve tri uhvate ideju; RAG i Graph precizniji o dvostrukoj odgovornosti | K11: Prema **Zakonu o obrani** (čl. 70.) i **Zakonu o službi u Oružanim snagama RH** (čl. 51.), **nacelnik Glavnog stožera** ima ključnu ulogu u lancu zapovijedanja i odgovornosti unutar Oružanih snaga (OSRH). Evo kako se to povezuje s ustavnom ulogom Predsjednika kao vrhovnog zapovjednika: 1. **Predsjednik kao vrhovni zapovjednik** (Ustav, čl. 100.) određuje strategiju i okvir djelovanja OSRH, ali **ne upravlja svakodnevnim operacijama**. Umjesto toga, delegira ovlasti **nacelniku Glavnog stožera** (Zakon o obrani, čl. 70.). 2. **Nacelnik Glavnog stožera** izvršava zapovijedi Predsjednika (čl. 70., stav. 1), ali i odluke ministra obrane (čl. 70., stav. 2). Njegova odgovornost uključuje: - Izvršavanje zadaća iz čl. 70. (npr. privremena pripravnost postrojbi u krizama, izvještavanje Predsjednika i ministra). - Raspoređivanje osoblja (čl. 51.): npr. brigadiri/generali (čl. 51., stav. 1–4) i niži stupnjevi (vojnici, dočasnici – čl. 51., stav. 6). 3. **Mehanizam odgovornosti**: Prema Ustavu (čl. 105.), Predsjednik može biti odgovaran ako krši Ustav, no Zakon o obrani (čl. 70., stav. 3) zahtijeva da nacelnik izvještava i Predsjednika i ministra o aktivnostima (npr. upotreba snaga u krizi). Time se osigurava nadzor i ravnoteža moći. **Zaključak**: Predisident definira strateške ciljeve, dok nacelnik Glavnog stožera vodi operativno vođenje OSRH, uz jasan pravni okvir odgovornosti prema najvišim institucijama. | L11: Ustav odreduje Predsjednika RH kao vrhovnog zapovjednika Oruzanih snaga. Zakon o obrani tu ulogu operacionalizira: Predsjednik nareduje uporabu OS u ratnom stanju i odgovoran je za obranu, dok se u nizim razinama ugroze odluke dijele s Vladom i Saborom. Nacelnik Glavnog stozera ima ovlast punog zapovijedanja u provedbi, pri cemu je za izvrsavanje zapovijedi i naredbi odgovoran Predsjedniku, a ministru obrane za provedbu odluka iz njegove nadleznosti. Zakon o sluzbi dodatno ureduje status i imenovanje nacelnika unutar vojne hijerarhije. Tako se ustavno nacelo civilnog vrhovnog zapovjednistva provodi kroz dvostruku liniju odgovornosti nacelnika GS.
A12: 9 | B12: Kompleksna – više dok. | C12: Usporedite kako se pripravnost, stanje neposredne ugrozenosti i ratno stanje odrazavaju na svakodnevni rezim u postrojbi (izlasci, osiguranje objekata, uzbuna) povezujuci Zakon o obrani s Pravilnikom o sluzbi u OSRH. | D12: 3 | E12: 3 | F12: 3 | G12: 3 | H12: 4 | I12: =AVERAGE(D12:H12) -> 3.2 | J12: RAG dobro pokriva stupnjeve; Graph fabricira URL-ove; Vanilla generičan | K12: Prema Zakonu o obrani (2025.) i Pravilniku o službi u Oružanim snagama Republike Hrvatske (2025.), pripremnost, stanje neposredne ugroženosti i ratno stanje imaju značajan utjecaj na svakodnevni režim u postrojbama. Evo usporedbe: ### **1. Pripravnost** - Prema **ZAKONU O OBRANI, članak 45.**, pripremnost uključuje aktivnosti za sprječavanje i uklanjanje opasnosti, uključujući i redovitu kontrolu objekata. - **PRAVILNIK O SLUŽBI U OSRH, članak 228.** navodi da se u stanju pripravnosti povećava oprez oko objekata, ali dnevni red ostaje relativno stabilan osim dodatnih inspekcija. ### **2. Stanje neposredne ugroženosti** - **ZAKON O OBRANI, članak 76.** definira ovo stanje kao aktivaciju mjera za sprječavanje napada. - **PRAVILNIK O SLUŽBI U OSRH, članak 20.** ograničava izlaske časnika bez dozvole, a prema **članku 10.**, povećava se nadzor objekata i pojačava straža. ### **3. Ratno stanje** - **ZAKON O OBRANI, članak 76., stavak 1.** nalaže potpunu mobilizaciju snaga. - **PRAVILNIK O SLUŽBI U OSRH, članak 20., stavak 2.** zabranjuje slobodno kretanje časnika bez dopuštenja zapovjednika, dok se prema **članku 154.** vojnici mogu smjestiti na poligonima bez povratka kući. ### **Zaključak** U stanju pripravnosti povećava se oprez, ali se dnevni red ne prekida znatno. U neposrednoj ugrozi i ratu dolazi do strogih ograničenja kretanja i pojačanog nadzora objekata, što utječe na cijeli vojnički život. *Napomena: Informacije su izvučene isključivo iz navedenih zakona i pravilnika. | L12: Zakon o obrani definira stupnjeve ugroze i tijela koja ih proglasavaju, a Pravilnik o sluzbi razraduje njihove operativne posljedice. Pri pripravnosti, stanju neposredne ugrozenosti ili ratnom stanju osiguranje objekata se pojacava (vise osoba, tehnicka i inzenjerijska sredstva), redoviti i izvanredni izlasci vojnih osoba ogranicavaju se ili obustavljaju, a privatna putovanja se obustavljaju kada je zapovjedena pripravnost. Uzbuna (borbena, mobilizacijska, zbog nesreca, radi provjere) dovodi postrojbu na trazeni stupanj spremnosti prikupljanjem na mjestima za uzbunu. Tako se pravni okvir (Zakon) preslikava u konkretne dnevne duznosti (Pravilnik).
